<?xml version="1.0"?>
<robot xmlns:xacro="http://wiki.ros.org/xacro">

    <material name="red">
      <color rgba="0.8 0.0 0.0 1.0"/>
    </material>
    <xacro:property name="cameraSize" value="0.02" /> <!-- Size of square 'camera' box -->
    <xacro:property name="cameraMass" value="0.1" /> <!-- Mass of square 'camera' box -->

    <joint name="camera_joint" type="revolute">
        <axis xyz="0 1 0" />
        <origin xyz="-0.3 0 0" rpy="0 0 ${-pi/2}"/>
        <parent link="forearm_link"/>
        <child link="camera_link"/>
        <limit lower="-2" upper="2" effort="330.0" velocity="3.14"/>
      </joint>
      <!-- Camera -->
      <link name="camera_link">
        <collision>
          <origin xyz="0 0 0" rpy="0 0 0"/>
          <geometry>
        <box size="${cameraSize} ${cameraSize} ${cameraSize}"/>
          </geometry>
        </collision>
    
        <visual>
          <origin xyz="0 0 0" rpy="0 0 0"/>
          <geometry>
        <box size="${cameraSize} ${cameraSize} ${cameraSize}"/>
          </geometry>
          <material name="red"/>
        </visual>
    
        <inertial>
          <mass value="${cameraMass}" />
          <origin xyz="0 0 0" rpy="0 0 0"/>
          <box_inertia m="${cameraMass}" x="${cameraSize}" y="${cameraSize}" z="${cameraSize}"/>>
          <inertia ixx="1e-6" ixy="0" ixz="0" iyy="1e-6" iyz="0" izz="1e-6" />
        </inertial>
      </link>
</robot>