<?xml version="1.0" encoding="utf-8" ?>
<!-- This URDF was automatically created by SolidWorks to URDF Exporter! Originally created by Stephen Brawner (brawner@gmail.com) 
     Commit Version: 1.6.0-4-g7f85cfe  Build Version: 1.6.7995.38578
     For more information, please see http://wiki.ros.org/sw_urdf_exporter -->
<robot name="exo_din">
    <link name="base_link">
        <inertial>
            <origin xyz="-0.083621 0.0087548 -0.18258" rpy="0 0 0" />
            <mass value="2.5151" />
            <inertia ixx="0.022882" ixy="2.2141E-06" ixz="-2.4105E-05" iyy="0.016089" iyz="2.9427E-06" izz="0.0083528" />
        </inertial>
        <visual>
            <origin xyz="0 0 0" rpy="0 0 0" />
            <geometry>
                <mesh filename="package://exo_din/meshes/base_link.STL" />
            </geometry>
            <material name="">
                <color rgba="0.74902 0.74902 0.74902 1" />
            </material>
        </visual>
        <collision>
            <origin xyz="0 0 0" rpy="0 0 0" />
            <geometry>
                <mesh filename="package://exo_din/meshes/base_link.STL" />
            </geometry>
        </collision>
    </link>
    <link name="link_1">
        <inertial>
            <origin xyz="0.00026832 0.11245 0.1143" rpy="0 0 0" />
            <mass value="1.1771" />
            <inertia ixx="0.0010591" ixy="6.9462E-07" ixz="-2.3971E-05" iyy="0.00080811" iyz="-2.4496E-05" izz="0.00047305" />
        </inertial>
        <visual>
            <origin xyz="0 0 0" rpy="0 0 0" />
            <geometry>
                <mesh filename="package://exo_din/meshes/link_1.STL" />
            </geometry>
            <material name="">
                <color rgba="0.75294 0.75294 0.75294 1" />
            </material>
        </visual>
        <collision>
            <origin xyz="0 0 0" rpy="0 0 0" />
            <geometry>
                <mesh filename="package://exo_din/meshes/link_1.STL" />
            </geometry>
        </collision>
    </link>
    <joint name="joint_1" type="revolute">
        <origin xyz="-0.15577 0.0088052 -0.26586" rpy="-0.00036153 -0.00029771 -3.1416" />
        <parent link="base_link" />
        <child link="link_1" />
        <axis xyz="0 0 -1" />
        <limit lower="-3.14" upper="3.14" effort="50" velocity="3.49" />
    </joint>
    <link name="link_2">
        <inertial>
            <origin xyz="0.0048091 0.19042 0.042951" rpy="0 0 0" />
            <mass value="1.1565" />
            <inertia ixx="0.0010511" ixy="-5.3021E-05" ixz="-1.3739E-07" iyy="0.00039937" iyz="-2.118E-06" izz="0.00087969" />
        </inertial>
        <visual>
            <origin xyz="0 0 0" rpy="0 0 0" />
            <geometry>
                <mesh filename="package://exo_din/meshes/link_2.STL" />
            </geometry>
            <material name="">
                <color rgba="0.75294 0.75294 0.75294 1" />
            </material>
        </visual>
        <collision>
            <origin xyz="0 0 0" rpy="0 0 0" />
            <geometry>
                <mesh filename="package://exo_din/meshes/link_2.STL" />
            </geometry>
        </collision>
    </link>
    <joint name="joint_2" type="revolute">
        <origin xyz="-0.03876 0.11791 0.13076" rpy="-3.1238 -1.5708 3.126" />
        <parent link="link_1" />
        <child link="link_2" />
        <axis xyz="0 0 -1" />
        <limit lower="-3.14" upper="3.14" effort="50" velocity="3.49" />
    </joint>
    <link name="link_3">
        <inertial>
            <origin xyz="-0.035914 0.18469 0.044015" rpy="0 0 0" />
            <mass value="1.1562" />
            <inertia ixx="0.0010315" ixy="0.0001235" ixz="-2.8739E-07" iyy="0.00041833" iyz="1.598E-06" izz="0.0008792" />
        </inertial>
        <visual>
            <origin xyz="0 0 0" rpy="0 0 0" />
            <geometry>
                <mesh filename="package://exo_din/meshes/link_3.STL" />
            </geometry>
            <material name="">
                <color rgba="0.75294 0.75294 0.75294 1" />
            </material>
        </visual>
        <collision>
            <origin xyz="0 0 0" rpy="0 0 0" />
            <geometry>
                <mesh filename="package://exo_din/meshes/link_3.STL" />
            </geometry>
        </collision>
    </link>
    <joint name="joint_3" type="revolute">
        <origin xyz="-0.03366 0.20656 0.046" rpy="1.5708 0 -1.6211" />
        <parent link="link_2" />
        <child link="link_3" />
        <axis xyz="0 0 -1" />
        <limit lower="-3.14" upper="3.14" effort="50" velocity="3.49" />
    </joint>
    <link name="link_4">
        <inertial>
            <origin xyz="-0.12254 0.22742 -0.030124" rpy="0 0 0" />
            <mass value="1.19" />
            <inertia ixx="0.00090778" ixy="0.00033737" ixz="-1.3858E-05" iyy="0.00062445" iyz="2.0378E-05" izz="0.0013155" />
        </inertial>
        <visual>
            <origin xyz="0 0 0" rpy="0 0 0" />
            <geometry>
                <mesh filename="package://exo_din/meshes/link_4.STL" />
            </geometry>
            <material name="">
                <color rgba="0.75294 0.75294 0.75294 1" />
            </material>
        </visual>
        <collision>
            <origin xyz="0 0 0" rpy="0 0 0" />
            <geometry>
                <mesh filename="package://exo_din/meshes/link_4.STL" />
            </geometry>
        </collision>
    </link>
    <joint name="joint_4" type="revolute">
        <origin xyz="0.0027746 0.20467 0.047" rpy="1.5708 0 1.7195" />
        <parent link="link_3" />
        <child link="link_4" />
        <axis xyz="0 0 -1" />
        <limit lower="-3.14" upper="3.14" effort="50" velocity="3.49" />
    </joint>
    <link name="link_5">
        <inertial>
            <origin xyz="-0.067675 -0.096987 -0.007807" rpy="0 0 0" />
            <mass value="0.073555" />
            <inertia ixx="0.00014301" ixy="-9.669E-05" ixz="7.936E-07" iyy="7.1908E-05" iyz="1.1339E-06" izz="0.00021197" />
        </inertial>
        <visual>
            <origin xyz="0 0 0" rpy="0 0 0" />
            <geometry>
                <mesh filename="package://exo_din/meshes/link_5.STL" />
            </geometry>
            <material name="">
                <color rgba="0.75294 0.75294 0.75294 1" />
            </material>
        </visual>
        <collision>
            <origin xyz="0 0 0" rpy="0 0 0" />
            <geometry>
                <mesh filename="package://exo_din/meshes/link_5.STL" />
            </geometry>
        </collision>
    </link>
    <joint name="joint_5" type="revolute">
        <origin xyz="-0.13159 0.24476 0.0099608" rpy="-0.00024377 0.0001709 2.1822" />
        <parent link="link_4" />
        <child link="link_5" />
        <axis xyz="0 0 -1" />
        <limit lower="-3.14" upper="3.14" effort="50" velocity="3.49" />
    </joint>
    <transmission name="trans_joint_1">
        <type>transmission_interface/SimpleTransmission</type>
        <joint name="joint_1">
            <hardwareInterface>hardware_interface/EffortJointInterface</hardwareInterface>
        </joint>
        <actuator name="joint_1_motor">
            <hardwareInterface>hardware_interface/EffortJointInterface</hardwareInterface>
            <mechanicalReduction>1</mechanicalReduction>
        </actuator>
    </transmission>
    <transmission name="trans_joint_2">
        <type>transmission_interface/SimpleTransmission</type>
        <joint name="joint_2">
            <hardwareInterface>hardware_interface/EffortJointInterface</hardwareInterface>
        </joint>
        <actuator name="joint_2_motor">
            <hardwareInterface>hardware_interface/EffortJointInterface</hardwareInterface>
            <mechanicalReduction>1</mechanicalReduction>
        </actuator>
    </transmission>
    <transmission name="trans_joint_3">
        <type>transmission_interface/SimpleTransmission</type>
        <joint name="joint_3">
            <hardwareInterface>hardware_interface/EffortJointInterface</hardwareInterface>
        </joint>
        <actuator name="joint_3_motor">
            <hardwareInterface>hardware_interface/EffortJointInterface</hardwareInterface>
            <mechanicalReduction>1</mechanicalReduction>
        </actuator>
    </transmission>
    <transmission name="trans_joint_4">
        <type>transmission_interface/SimpleTransmission</type>
        <joint name="joint_4">
            <hardwareInterface>hardware_interface/EffortJointInterface</hardwareInterface>
        </joint>
        <actuator name="joint_4_motor">
            <hardwareInterface>hardware_interface/EffortJointInterface</hardwareInterface>
            <mechanicalReduction>1</mechanicalReduction>
        </actuator>
    </transmission>
    <transmission name="trans_joint_5">
        <type>transmission_interface/SimpleTransmission</type>
        <joint name="joint_5">
            <hardwareInterface>hardware_interface/EffortJointInterface</hardwareInterface>
        </joint>
        <actuator name="joint_5_motor">
            <hardwareInterface>hardware_interface/EffortJointInterface</hardwareInterface>
            <mechanicalReduction>1</mechanicalReduction>
        </actuator>
    </transmission>
    <gazebo>
        <plugin name="gazebo_ros_control">
            <robotNamespace>/</robotNamespace>
        </plugin>
    </gazebo>
</robot>
