<?xml version="1.0" encoding="utf-8"?>
<!-- This URDF was automatically created by SolidWorks to URDF Exporter! Originally created by Stephen Brawner (brawner@gmail.com) 
     Commit Version: 1.6.0-4-g7f85cfe  Build Version: 1.6.7995.38578
     For more information, please see http://wiki.ros.org/sw_urdf_exporter -->
<robot
  name="Exo">
  <link
    name="base_link">
    <inertial>
      <origin
        xyz="-0.083621 -0.18258 -0.0087548"
        rpy="0 0 0" />
      <mass
        value="2.5151" />
      <inertia
        ixx="0.022882"
        ixy="-2.4105E-05"
        ixz="-2.2141E-06"
        iyy="0.0083528"
        iyz="-2.9427E-06"
        izz="0.016089" />
    </inertial>
    <visual>
      <origin
        xyz="0 0 0"
        rpy="0 0 0" />
      <geometry>
        <mesh
          filename="package://Exo/meshes/base_link.STL" />
      </geometry>
      <material
        name="">
        <color
          rgba="0.74902 0.74902 0.74902 1" />
      </material>
    </visual>
    <collision>
      <origin
        xyz="0 0 0"
        rpy="0 0 0" />
      <geometry>
        <mesh
          filename="package://Exo/meshes/base_link.STL" />
      </geometry>
    </collision>
  </link>
  <link
    name="link_1">
    <inertial>
      <origin
        xyz="0.015315 0.1114 0.1143"
        rpy="0 0 0" />
      <mass
        value="1.1771" />
      <inertia
        ixx="0.0010548"
        ixy="-3.2613E-05"
        ixz="-2.7034E-05"
        iyy="0.00081243"
        iyz="-2.1067E-05"
        izz="0.00047305" />
    </inertial>
    <visual>
      <origin
        xyz="0 0 0"
        rpy="0 0 0" />
      <geometry>
        <mesh
          filename="package://Exo/meshes/link_1.STL" />
      </geometry>
      <material
        name="">
        <color
          rgba="0.75294 0.75294 0.75294 1" />
      </material>
    </visual>
    <collision>
      <origin
        xyz="0 0 0"
        rpy="0 0 0" />
      <geometry>
        <mesh
          filename="package://Exo/meshes/link_1.STL" />
      </geometry>
    </collision>
  </link>
  <joint
    name="Joint_1"
    type="revolute">
    <origin
      xyz="-0.15577 0.0088052 -0.26586"
      rpy="-0.00036153 -0.00029771 -3.1416" />
    <parent
      link="base_link" />
    <child
      link="link_1" />
    <axis
      xyz="0 0 -1" />
    <limit
      lower="-3.14"
      upper="3.14"
      effort="50"
      velocity="3.49" />
  </joint>
  <link
    name="link_2">
    <inertial>
      <origin
        xyz="-0.0049684 0.19041 0.042949"
        rpy="0 0 0" />
      <mass
        value="1.1565" />
      <inertia
        ixx="0.0010548"
        ixy="-1.9387E-05"
        ixz="2.3509E-08"
        iyy="0.00039566"
        iyz="-2.1281E-06"
        izz="0.00087969" />
    </inertial>
    <visual>
      <origin
        xyz="0 0 0"
        rpy="0 0 0" />
      <geometry>
        <mesh
          filename="package://Exo/meshes/link_2.STL" />
      </geometry>
      <material
        name="">
        <color
          rgba="0.75294 0.75294 0.75294 1" />
      </material>
    </visual>
    <collision>
      <origin
        xyz="0 0 0"
        rpy="0 0 0" />
      <geometry>
        <mesh
          filename="package://Exo/meshes/link_2.STL" />
      </geometry>
    </collision>
  </link>
  <joint
    name="joint_2"
    type="revolute">
    <origin
      xyz="-0.022632 0.12204 0.13076"
      rpy="0 -1.5705 -0.13202" />
    <parent
      link="link_1" />
    <child
      link="link_2" />
    <axis
      xyz="0.00029771 0 -1" />
    <limit
      lower="-3.14"
      upper="3.14"
      effort="50"
      velocity="3.49" />
  </joint>
  <link
    name="link_3">
    <inertial>
      <origin
        xyz="0.01069 -0.18785 0.044015"
        rpy="0 0 0" />
      <mass
        value="1.1562" />
      <inertia
        ixx="0.0010533"
        ixy="3.7117E-05"
        ixz="6.9363E-08"
        iyy="0.00039648"
        iyz="-1.6221E-06"
        izz="0.0008792" />
    </inertial>
    <visual>
      <origin
        xyz="0 0 0"
        rpy="0 0 0" />
      <geometry>
        <mesh
          filename="package://Exo/meshes/link_3.STL" />
      </geometry>
      <material
        name="">
        <color
          rgba="0.75294 0.75294 0.75294 1" />
      </material>
    </visual>
    <collision>
      <origin
        xyz="0 0 0"
        rpy="0 0 0" />
      <geometry>
        <mesh
          filename="package://Exo/meshes/link_3.STL" />
      </geometry>
    </collision>
  </link>
  <joint
    name="joint_3"
    type="revolute">
    <origin
      xyz="-0.044215 0.20456 0.045987"
      rpy="-1.5711 0 1.5718" />
    <parent
      link="link_2" />
    <child
      link="link_3" />
    <axis
      xyz="0 0 -1" />
    <limit
      lower="-3.14"
      upper="3.14"
      effort="50"
      velocity="3.49" />
  </joint>
  <link
    name="link_4">
    <inertial>
      <origin
        xyz="0.054034 0.25263 -0.030072"
        rpy="0 0 0" />
      <mass
        value="1.19" />
      <inertia
        ixx="0.0011218"
        ixy="-8.5772E-05"
        ixz="2.6176E-06"
        iyy="0.00041039"
        iyz="2.432E-05"
        izz="0.0013155" />
    </inertial>
    <visual>
      <origin
        xyz="0 0 0"
        rpy="0 0 0" />
      <geometry>
        <mesh
          filename="package://Exo/meshes/link_4.STL" />
      </geometry>
      <material
        name="">
        <color
          rgba="0.75294 0.75294 0.75294 1" />
      </material>
    </visual>
    <collision>
      <origin
        xyz="0 0 0"
        rpy="0 0 0" />
      <geometry>
        <mesh
          filename="package://Exo/meshes/link_4.STL" />
      </geometry>
    </collision>
  </link>
  <joint
    name="joint_4"
    type="revolute">
    <origin
      xyz="-0.030338 -0.20242 0.047"
      rpy="1.5708 0 -1.5573" />
    <parent
      link="link_3" />
    <child
      link="link_4" />
    <axis
      xyz="0.00029771 0 -1" />
    <limit
      lower="-3.14"
      upper="3.14"
      effort="50"
      velocity="3.49" />
  </joint>
  <link
    name="link_5">
    <inertial>
      <origin
        xyz="0.005486 -0.11814 -0.007807"
        rpy="0 0 0" />
      <mass
        value="0.073555" />
      <inertia
        ixx="0.00021003"
        ixy="9.5448E-06"
        ixz="-6.2259E-08"
        iyy="4.8819E-06"
        iyz="1.3827E-06"
        izz="0.00021197" />
    </inertial>
    <visual>
      <origin
        xyz="0 0 0"
        rpy="0 0 0" />
      <geometry>
        <mesh
          filename="package://Exo/meshes/link_5.STL" />
      </geometry>
      <material
        name="">
        <color
          rgba="0.75294 0.75294 0.75294 1" />
      </material>
    </visual>
    <collision>
      <origin
        xyz="0 0 0"
        rpy="0 0 0" />
      <geometry>
        <mesh
          filename="package://Exo/meshes/link_5.STL" />
      </geometry>
    </collision>
  </link>
  <joint
    name="joint_5"
    type="revolute">
    <origin
      xyz="0.058369 0.27168 0.010017"
      rpy="-0.00029641 -2.7787E-05 1.4773" />
    <parent
      link="link_4" />
    <child
      link="link_5" />
    <axis
      xyz="0 0 -1" />
    <limit
      lower="-3.14"
      upper="3.14"
      effort="50"
      velocity="3.49" />
  </joint>
</robot>