<?xml version="1.0" encoding="utf-8" ?>
<!-- This URDF was automatically created by SolidWorks to URDF Exporter! Originally created by Stephen Brawner (brawner@gmail.com) 
     Commit Version: 1.6.0-4-g7f85cfe  Build Version: 1.6.7995.38578
     For more information, please see http://wiki.ros.org/sw_urdf_exporter -->
<robot name="camera_mechanism_movment">
    <link name="base_link">
        <inertial>
            <origin xyz="-1.042E-08 -0.0034422 0.026198" rpy="0 0 0" />
            <mass value="0.090334" />
            <inertia ixx="6.8467E-05" ixy="5.9979E-12" ixz="1.3439E-12" iyy="6.5123E-05" iyz="-1.8873E-07" izz="0.00010174" />
        </inertial>
        <visual>
            <origin xyz="0 0 0" rpy="0 0 0" />
            <geometry>
                <mesh filename="package://camera_mechanism_movment/meshes/base_link.STL" />
            </geometry>
            <material name="">
                <color rgba="0.79216 0.81961 0.93333 1" />
            </material>
        </visual>
        <collision>
            <origin xyz="0 0 0" rpy="0 0 0" />
            <geometry>
                <mesh filename="package://camera_mechanism_movment/meshes/base_link.STL" />
            </geometry>
        </collision>
    </link>
    <link name="link_1">
        <inertial>
            <origin xyz="-0.00274428257190968 -0.00020748847805208 0.0169598693710931" rpy="0 0 0" />
            <mass value="0.0762928038541526" />
            <inertia ixx="2.78524913265596E-05" ixy="1.44751279636948E-08" ixz="7.79881822675902E-07" iyy="1.38848895102569E-05" iyz="1.4640337530444E-08" izz="3.46925557643959E-05" />
        </inertial>
        <visual>
            <origin xyz="0 0 0" rpy="0 0 0" />
            <geometry>
                <mesh filename="package://camera_mechanism_movment/meshes/link_1.STL" />
            </geometry>
            <material name="">
                <color rgba="0.752941176470588 0.752941176470588 0.752941176470588 1" />
            </material>
        </visual>
        <collision>
            <origin xyz="0 0 0" rpy="0 0 0" />
            <geometry>
                <mesh filename="package://camera_mechanism_movment/meshes/link_1.STL" />
            </geometry>
        </collision>
    </link>
    <joint name="joint_1" type="revolute">
        <origin xyz="0 0 0.045256" rpy="0 0 0" />
        <parent link="base_link" />
        <child link="link_1" />
        <axis xyz="0 0 -1" />
        <limit lower="-1.5708" upper="1.5708" effort="15" velocity="137" />
    </joint>
    <link name="link_2">
        <inertial>
            <origin xyz="0.00319069336561053 0.0467174118427644 0.0302711238523648" rpy="0 0 0" />
            <mass value="0.0760046548351893" />
            <inertia ixx="8.75759430262867E-05" ixy="-3.75975452138231E-08" ixz="-8.26121264442182E-07" iyy="8.43979936608012E-05" iyz="3.14738619919505E-08" izz="1.01097278745386E-05" />
        </inertial>
        <visual>
            <origin xyz="0 0 0" rpy="0 0 0" />
            <geometry>
                <mesh filename="package://camera_mechanism_movment/meshes/link_2.STL" />
            </geometry>
            <material name="">
                <color rgba="0.792156862745098 0.819607843137255 0.933333333333333 1" />
            </material>
        </visual>
        <collision>
            <origin xyz="0 0 0" rpy="0 0 0" />
            <geometry>
                <mesh filename="package://camera_mechanism_movment/meshes/link_2.STL" />
            </geometry>
        </collision>
    </link>
    <joint name="joint_2" type="revolute">
        <origin xyz="0.029615 -0.010178 0.021744" rpy="1.5708 0 -1.5708" />
        <parent link="link_1" />
        <child link="link_2" />
        <axis xyz="0 0 1" />
        <limit lower="-1.5708" upper="1.5708" effort="15" velocity="137" />
    </joint>
    <transmission name="trans_joint_1">
        <type>transmission_interface/SimpleTransmission</type>
        <joint name="joint_1">
            <hardwareInterface>hardware_interface/EffortJointInterface</hardwareInterface>
        </joint>
        <actuator name="joint_1_motor">
            <hardwareInterface>hardware_interface/EffortJointInterface</hardwareInterface>
            <mechanicalReduction>1</mechanicalReduction>
        </actuator>
    </transmission>
    <transmission name="trans_joint_2">
        <type>transmission_interface/SimpleTransmission</type>
        <joint name="joint_2">
            <hardwareInterface>hardware_interface/EffortJointInterface</hardwareInterface>
        </joint>
        <actuator name="joint_2_motor">
            <hardwareInterface>hardware_interface/EffortJointInterface</hardwareInterface>
            <mechanicalReduction>1</mechanicalReduction>
        </actuator>
    </transmission>
    <gazebo>
        <plugin name="gazebo_ros_control">
            <robotNamespace>/</robotNamespace>
        </plugin>
    </gazebo>
</robot>

