<?xml version="1.0" encoding="utf-8" ?>
<!-- This URDF was automatically created by SolidWorks to URDF Exporter! Originally created by Stephen Brawner (brawner@gmail.com) 
     Commit Version: 1.6.0-4-g7f85cfe  Build Version: 1.6.7995.38578
     For more information, please see http://wiki.ros.org/sw_urdf_exporter -->
<robot name="exoskelaton_model">
    <link name="world" />
    <joint name="world_to_base_link=" type="fixed">
        <parent link="world" />
        <child link="base_link" />
    </joint>
    <link name="base_link">
        <inertial>
            <origin xyz="-0.0836207176577604 0.00875481719950126 -0.182578110095897" rpy="0 0 0" />
            <mass value="2.51510979215834" />
            <inertia ixx="0.0228818124596641" ixy="2.21405760466253E-06" ixz="-2.41054719117493E-05" iyy="0.0160894130168314" iyz="2.94271508438108E-06" izz="0.00835275247773463" />
        </inertial>
        <visual>
            <origin xyz="0 0 0" rpy="0 0 0" />
            <geometry>
                <mesh filename="package://exoskelaton_model/meshes/base_link.STL" />
            </geometry>
            <material name="">
                <color rgba="0.749019607843137 0.749019607843137 0.749019607843137 1" />
            </material>
        </visual>
        <collision>
            <origin xyz="0 0 0" rpy="0 0 0" />
            <geometry>
                <mesh filename="package://exoskelaton_model/meshes/base_link.STL" />
            </geometry>
        </collision>
    </link>
    <link name="link_1">
        <inertial>
            <origin xyz="0.00051632 0.11245 0.1143" rpy="0 0 0" />
            <mass value="1.1771" />
            <inertia ixx="0.0010591" ixy="1.4114E-07" ixz="-2.4025E-05" iyy="0.00080811" iyz="-2.4443E-05" izz="0.00047305" />
        </inertial>
        <visual>
            <origin xyz="0 0 0" rpy="0 0 0" />
            <geometry>
                <mesh filename="package://exoskelaton_model/meshes/link_1.STL" />
            </geometry>
            <material name="">
                <color rgba="0.75294 0.75294 0.75294 1" />
            </material>
        </visual>
        <collision>
            <origin xyz="0 0 0" rpy="0 0 0" />
            <geometry>
                <mesh filename="package://exoskelaton_model/meshes/link_1.STL" />
            </geometry>
        </collision>
    </link>
    <joint name="joint_1" type="revolute">
        <origin xyz="-0.15576841452816 0.00880518561429395 -0.265864926099811" rpy="-0.00036152630959631 -0.000297710155103675 -3.14159254595974" />
        <parent link="base_link" />
        <child link="link_1" />
        <axis xyz="0 0 -1" />
        <limit lower="-3.14" upper="3.14" effort="50" velocity="3.49" />
    </joint>
    <link name="link_2">
        <inertial>
            <origin xyz="-0.0047682 0.19042 0.042951" rpy="0 0 0" />
            <mass value="1.1565" />
            <inertia ixx="0.0010548" ixy="-2.0035E-05" ixz="-3.0714E-08" iyy="0.00039569" iyz="-2.1223E-06" izz="0.00087969" />
        </inertial>
        <visual>
            <origin xyz="0 0 0" rpy="0 0 0" />
            <geometry>
                <mesh filename="package://exoskelaton_model/meshes/link_2.STL" />
            </geometry>
            <material name="">
                <color rgba="0.75294 0.75294 0.75294 1" />
            </material>
        </visual>
        <collision>
            <origin xyz="0 0 0" rpy="0 0 0" />
            <geometry>
                <mesh filename="package://exoskelaton_model/meshes/link_2.STL" />
            </geometry>
        </collision>
    </link>
    <joint name="joint_2" type="revolute">
        <origin xyz="-0.0385000000000007 0.117999999999999 0.130760035281312" rpy="-0.037127716917956 -1.57079631189374 0.0371631202033193" />
        <parent link="link_1" />
        <child link="link_2" />
        <axis xyz="0 0 -1" />
        <limit lower="-3.14" upper="3.14" effort="50" velocity="3.49" />
    </joint>
    <link name="link_3">
        <inertial>
            <origin xyz="-0.0082161 0.18797 0.044015" rpy="0 0 0" />
            <mass value="1.1562" />
            <inertia ixx="0.0010542" ixy="2.8457E-05" ixz="-4.9159E-08" iyy="0.00039561" iyz="1.6209E-06" izz="0.0008792" />
        </inertial>
        <visual>
            <origin xyz="0 0 0" rpy="0 0 0" />
            <geometry>
                <mesh filename="package://exoskelaton_model/meshes/link_3.STL" />
            </geometry>
            <material name="">
                <color rgba="0.75294 0.75294 0.75294 1" />
            </material>
        </visual>
        <collision>
            <origin xyz="0 0 0" rpy="0 0 0" />
            <geometry>
                <mesh filename="package://exoskelaton_model/meshes/link_3.STL" />
            </geometry>
        </collision>
    </link>
    <joint name="joint_3" type="revolute">
        <origin xyz="-0.0440000000000005 0.204606049200406 0.045999999999999" rpy="1.57079632679491 0 -1.5707963267949" />
        <parent link="link_2" />
        <child link="link_3" />
        <axis xyz="0 0 -1" />
        <limit lower="-3.14" upper="3.14" effort="50" velocity="3.49" />
    </joint>
    <link name="link_4">
        <inertial>
            <origin xyz="0.030218 0.25657 -0.030079" rpy="0 0 0" />
            <mass value="1.19" />
            <inertia ixx="0.0011316" ixy="-1.8161E-05" ixz="3.377E-07" iyy="0.00040064" iyz="2.4483E-05" izz="0.0013155" />
        </inertial>
        <visual>
            <origin xyz="0 0 0" rpy="0 0 0" />
            <geometry>
                <mesh filename="package://exoskelaton_model/meshes/link_4.STL" />
            </geometry>
            <material name="">
                <color rgba="0.75294 0.75294 0.75294 1" />
            </material>
        </visual>
        <collision>
            <origin xyz="0 0 0" rpy="0 0 0" />
            <geometry>
                <mesh filename="package://exoskelaton_model/meshes/link_4.STL" />
            </geometry>
        </collision>
    </link>
    <joint name="joint_4" type="revolute">
        <origin xyz="0.0330000000000062 0.202007049200406 0.0469999999999915" rpy="1.5707963267949 0 1.57109403696946" />
        <parent link="link_3" />
        <child link="link_4" />
        <axis xyz="0.00029771017016183 0 -0.999999955684326" />
        <limit lower="-3.14" upper="3.14" effort="50" velocity="3.49" />
    </joint>
    <link name="link_5">
        <inertial>
            <origin xyz="3.5672E-06 -0.11826 -0.007807" rpy="0 0 0" />
            <mass value="0.073555" />
            <inertia ixx="0.00021048" ixy="3.6788E-09" ixz="1.899E-09" iyy="4.4387E-06" iyz="1.3841E-06" izz="0.00021197" />
        </inertial>
        <visual>
            <origin xyz="0 0 0" rpy="0 0 0" />
            <geometry>
                <mesh filename="package://exoskelaton_model/meshes/link_5.STL" />
            </geometry>
            <material name="">
                <color rgba="0.75294 0.75294 0.75294 1" />
            </material>
        </visual>
        <collision>
            <origin xyz="0 0 0" rpy="0 0 0" />
            <geometry>
                <mesh filename="package://exoskelaton_model/meshes/link_5.STL" />
            </geometry>
        </collision>
    </link>
    <joint name="joint_5" type="revolute">
        <origin xyz="0.032755858725567 0.275947208661753 0.0100097521958599" rpy="-0.000297710174561625 0 1.57079632679491" />
        <parent link="link_4" />
        <child link="link_5" />
        <axis xyz="0 0 -1" />
        <limit lower="-3.14" upper="3.14" effort="50" velocity="3.49" />
    </joint>
    <transmission name="trans_joint_1">
        <type>transmission_interface/SimpleTransmission</type>
        <joint name="joint_1">
            <hardwareInterface>hardware_interface/EffortJointInterface</hardwareInterface>
        </joint>
        <actuator name="joint_1_motor">
            <hardwareInterface>hardware_interface/EffortJointInterface</hardwareInterface>
            <mechanicalReduction>1</mechanicalReduction>
        </actuator>
    </transmission>
    <transmission name="trans_joint_2">
        <type>transmission_interface/SimpleTransmission</type>
        <joint name="joint_2">
            <hardwareInterface>hardware_interface/EffortJointInterface</hardwareInterface>
        </joint>
        <actuator name="joint_2_motor">
            <hardwareInterface>hardware_interface/EffortJointInterface</hardwareInterface>
            <mechanicalReduction>1</mechanicalReduction>
        </actuator>
    </transmission>
    <transmission name="trans_joint_3">
        <type>transmission_interface/SimpleTransmission</type>
        <joint name="joint_3">
            <hardwareInterface>hardware_interface/EffortJointInterface</hardwareInterface>
        </joint>
        <actuator name="joint_3_motor">
            <hardwareInterface>hardware_interface/EffortJointInterface</hardwareInterface>
            <mechanicalReduction>1</mechanicalReduction>
        </actuator>
    </transmission>
    <transmission name="trans_joint_4">
        <type>transmission_interface/SimpleTransmission</type>
        <joint name="joint_4">
            <hardwareInterface>hardware_interface/EffortJointInterface</hardwareInterface>
        </joint>
        <actuator name="joint_4_motor">
            <hardwareInterface>hardware_interface/EffortJointInterface</hardwareInterface>
            <mechanicalReduction>1</mechanicalReduction>
        </actuator>
    </transmission>
    <transmission name="trans_joint_5">
        <type>transmission_interface/SimpleTransmission</type>
        <joint name="joint_5">
            <hardwareInterface>hardware_interface/EffortJointInterface</hardwareInterface>
        </joint>
        <actuator name="joint_5_motor">
            <hardwareInterface>hardware_interface/EffortJointInterface</hardwareInterface>
            <mechanicalReduction>1</mechanicalReduction>
        </actuator>
    </transmission>
    <gazebo>
        <plugin name="gazebo_ros_control" filename="libgazebo_ros_control.so">
            <robotNamespace>/exoskelaton</robotNamespace>
        </plugin>
    </gazebo>
    <gazebo reference="base_link">
        <mu1>0.2</mu1>
        <mu2>0.2</mu2>
        <kd>0.2</kd>
        <gravity>0</gravity>
    </gazebo>
    <gazebo reference="link_1">
        <mu1>0.2</mu1>
        <mu2>0.2</mu2>
        <kd>0.2</kd>
        <gravity>0</gravity>
    </gazebo>
    <gazebo reference="link_2">
        <mu1>0.2</mu1>
        <mu2>0.2</mu2>
        <kd>0.2</kd>
        <gravity>0</gravity>
    </gazebo>
    <gazebo reference="link_3">
        <mu1>0.2</mu1>
        <mu2>0.2</mu2>
        <kd>0.2</kd>
        <gravity>0</gravity>
    </gazebo>
    <gazebo reference="link_4">
        <mu1>0.2</mu1>
        <mu2>0.2</mu2>
        <kd>0.2</kd>
        <gravity>0</gravity>
    </gazebo>
    <gazebo reference="link_5">
        <mu1>0.2</mu1>
        <mu2>0.2</mu2>
        <kd>0.2</kd>
        <gravity>0</gravity>
    </gazebo>
</robot>
